Workbook

Sheet Summary
B2: Tata Consumer x Capital Foods (Ching's Secret): Commercial Due Diligence & Valuation
B5: Deal snapshot
B6: Enterprise value paid (100%) | C6: =Inputs!$C$6 -> 5100
B7: EV / FY24E net sales | C7: =Precedents!H14 -> 6.8
B8: EV / FY24E EBITDA | C8: =Precedents!F23 -> 34
B9: Precedent median EV / sales (4 Indian FMCG deals) | C9: =Precedents!H11 -> 4.9067397
B10: TCPL's own market cap / sales | C10: =Precedents!F21 -> 6.5763514
B12: Valuation verdict
C13: Management | D13: Base | E13: Downside
B14: Standalone DCF value | C14: ='Business Plan & DCF'!C22 -> 5595.1061 | D14: ='Business Plan & DCF'!C40 -> 3169.3071 | E14: ='Business Plan & DCF'!C58 -> 2274.4522
B15: Plus: value of synergies | C15: =Synergies!$C$20 -> 859.13479 | D15: =Synergies!$C$20 -> 859.13479 | E15: =Synergies!$C$20 -> 859.13479
B16: Value to TCPL | C16: =C14+C15 -> 6454.2409 | D16: =D14+D15 -> 4028.4419 | E16: =E14+E15 -> 3133.587
B17: Value created / (overpaid) vs. Rs 5,100 cr | C17: =C16-Inputs!$C$6 -> 1354.2409 | D17: =D16-Inputs!$C$6 -> -1071.5581 | E17: =E16-Inputs!$C$6 -> -1966.413
B18: FY25-29 revenue CAGR in case | C18: =Market!C16 -> 0.23381107 | D18: =Market!C17 -> 0.14 | E18: =Market!C18 -> 0.086918664
B19: FY25 plan vs. FY25 actual revenue | C19: ='Business Plan & DCF'!C25 -> -0.15449735 | D19: ='Business Plan & DCF'!C43 -> -0.065497076 | E19: ='Business Plan & DCF'!C61 -> 0.00031298905
B21: Key findings (numbers update with the model)
B22: ="1. Attractive market: relevant categories grow at ~"&TEXT(Market!C7,"0%")&" a year to Rs "&TEXT(Inputs!$C$19,"#,##0")&" cr by 2027, and Capital Foods leads Schezwan chutney with an 87% share." -> 1. Attractive market: relevant categories grow at ~14% a year to Rs 41,600 cr by 2027, and Capital Foods leads Schezwan chutney with an 87% share.
B23: ="2. Full price: Rs 5,100 cr is "&TEXT(C7,"0.0")&"x sales and "&TEXT(C8,"0")&"x EBITDA, above the "&TEXT(C9,"0.0")&"x precedent median, close to TCPL's own "&TEXT(C10,"0.0")&"x." -> 2. Full price: Rs 5,100 cr is 6.8x sales and 34x EBITDA, above the 4.9x precedent median, close to TCPL's own 6.6x.
B24: ="3. The price needs the growth thesis: value to TCPL is Rs "&TEXT(C16,"#,##0")&" cr in the management case but Rs "&TEXT(D16,"#,##0")&" cr in the base case, vs. Rs 5,100 cr paid." -> 3. The price needs the growth thesis: value to TCPL is Rs 6,454 cr in the management case but Rs 4,028 cr in the base case, vs. Rs 5,100 cr paid.
B25: ="4. Year 1 undershot: FY25 revenue grew "&TEXT(Market!C15,"0.0%")&", "&TEXT(Market!D15,"0.0")&"x the market rate vs. the ~2x thesis; distribution synergies are the key lever." -> 4. Year 1 undershot: FY25 revenue grew 6.5%, 0.5x the market rate vs. the ~2x thesis; distribution synergies are the key lever.
B26: ="5. EPS impact ("&Accretion!C32&" case): "&TEXT(Accretion!D28,"0.0%;-0.0%")&" in FY25 and "&TEXT(Accretion!E28,"0.0%;-0.0%")&" in FY26, vs. TCPL guidance of EPS breakeven in year 2." -> 5. EPS impact (Base case): -11.2% in FY25 and -6.0% in FY26, vs. TCPL guidance of EPS breakeven in year 2.
B28: How to use
B29: Edit blue cells on 'Inputs' only; yellow cells are the main levers (case switch, synergies, debt cost, funding mix).
B30: Facts tagged [n] are sourced (see 'Sources'); everything else is an analyst assumption and is labelled as such.
B31: Sheets: Market > Business Plan & DCF > Synergies > Precedents > Accretion > Sensitivity > Football Field.
B33: Colour legend
B34: Blue: hardcoded input
B35: Black: formula
B36: Green: link to another sheet
B37: Yellow fill: key lever
B38: Green fill: key output

Sheet Inputs
B2: Inputs & Assumptions
B3: Blue = hardcoded input; yellow = key lever. [n] = sourced fact (see Sources); 'Analyst assumption' = my estimate, flex it. Rs. crore unless stated.
B5: Deal terms
B6: Enterprise value paid for 100% of Capital Foods | C6: 5100 | D6: Rs. cr | J6: [1] [2] 75% upfront, balance 25% within 3 years; all-cash
B7: Stake acquired upfront | C7: 0.75 | J7: [1] Model consolidates 100% (balance stake committed within 3 years)
B8: TCPL share price at announcement (12 Jan 2024) | C8: 1152.05 | D8: Rs. | J8: [3]
B9: Capital Foods net revenue, FY24E | C9: 750 | D9: Rs. cr | J9: [1] ~Rs 750 cr net (Rs 936 cr gross); deal = 6.8x FY24E net sales
B10: Capital Foods revenue, FY23 (actual) | C10: 705.5 | D10: Rs. cr | J10: [2]
B11: Capital Foods revenue, FY25 (actual, post-deal) | C11: 799 | D11: Rs. cr | J11: [7]
B12: Capital Foods profit, FY25 (actual) | C12: 119 | D12: Rs. cr | J12: [7]
B13: Capital Foods EBITDA margin, FY24E | C13: 0.2 | J13: [1] '20%+'; 20% used as a conservative floor
B14: Capital Foods gross margin | C14: 0.5 | J14: [1] ~50%
B15: Exports as % of Capital Foods revenue | C15: 0.17 | J15: [1] ~17%
B17: Market (Capital Foods' relevant categories)
B18: Relevant market size, 2022 | C18: 21400 | D18: Rs. cr | J18: [1] Chutneys, Chinese sauces, instant noodles, blended masalas, GGP, soups
B19: Relevant market size, 2027F | C19: 41600 | D19: Rs. cr | J19: [1]
B20: Capital Foods retail reach | C20: 0.4 | D20: mn outlets | J20: [1] ~0.35-0.4 mn stores (Nielsen urban reach, Jan 2023)
B21: TCPL retail reach | C21: 3.8 | D21: mn outlets | J21: [1] FY23
B23: Acquirer: Tata Consumer Products (TCPL)
B24: TCPL revenue, FY24 | C24: 15206 | D24: Rs. cr | J24: [5]
B25: TCPL EBITDA, FY24 | C25: 2323 | D25: Rs. cr | J25: [5]
B26: TCPL consolidated net profit, FY24 | C26: 1150.33 | D26: Rs. cr | J26: [6]
B27: TCPL market capitalisation (5 Jan 2024) | C27: 100000 | D27: Rs. cr | J27: [1] ~Rs 1 lakh cr
B28: TCPL shares outstanding pre-rights | C28: 95.16 | D28: crore | J28: Derived from [4]: 3.66 cr rights shares at a 1:26 ratio
B29: TCPL standalone net profit growth p.a. | C29: 0.1 | J29: Analyst assumption
B30: Tax rate | C30: 0.25 | J30: Approximates India's 25.17% concessional regime
B32: Funding (TCPL raised Rs 6,500 cr for Rs 7,000 cr of deals)
B33: Rights issue size | C33: 3000 | D33: Rs. cr | J33: [3] [4]
B34: Rights issue price | C34: 818 | D34: Rs. | J34: [4] 35% discount to market
B35: Combined EV of both deals (Capital Foods + Organic India) | C35: 7000 | D35: Rs. cr | J35: [2]
B36: Share of Capital Foods price funded by equity | C36: =C33/C35 -> 0.42857143 | J36: Pro rata allocation of the rights issue across the two deals
B37: Pre-tax cost of acquisition debt (CP / NCD) | C37: 0.0775 | J37: Analyst assumption: AAA commercial paper yields in early 2024
B38: Share of EV allocated to amortisable intangibles | C38: 0.15 | J38: Analyst assumption; brands with indefinite life and goodwill are not amortised (Ind AS 38/103)
B39: Amortisation life | C39: 15 | D39: years | J39: Analyst assumption
B40: One-off integration cost (FY25) | C40: 40 | D40: Rs. cr | J40: Analyst assumption
B42: Valuation
B43: Risk-free rate (India 10Y G-Sec, Jan 2024) | C43: 0.072 | J43: Approximate yield at announcement
B44: Beta | C44: 0.6 | J44: Analyst assumption: Indian staples betas typically 0.5-0.7
B45: Equity risk premium | C45: 0.055 | J45: Analyst assumption
B46: Terminal growth | C46: 0.055 | J46: Analyst assumption: long-run nominal growth for Indian packaged foods
...

Sheet Market
B2: Market Assessment: Is Capital Foods in an attractive, growing market?
B3: Relevant categories: chutneys, Chinese sauces, instant noodles, blended masalas, ginger-garlic paste, soups. Rs. crore.
B5: Market growth path (top-down, from TCPL's deal presentation [1])
B6: Rs. crore | C6: 2022 | D6: 2023 | E6: 2024 | F6: 2025 | G6: 2026 | H6: 2027F
B7: Implied CAGR 2022-27 | C7: =(Inputs!$C$19/Inputs!$C$18)^(1/5)-1 -> 0.14218358
B8: Relevant market size | C8: =Inputs!$C$18 -> 21400 | D8: =C8*(1+$C$7) -> 24442.729 | E8: =D8*(1+$C$7) -> 27918.083 | F8: =E8*(1+$C$7) -> 31887.576 | G8: =F8*(1+$C$7) -> 36421.466 | H8: =G8*(1+$C$7) -> 41600
B9: Capital Foods share (FY24E revenue / 2024 market) | E9: =Inputs!$C$9/E8 -> 0.026864309
B11: Thesis check: does Capital Foods grow ~2x the market?
C12: Growth | D12: vs. market
B13: Relevant market CAGR 2022-27 | C13: =C7 -> 0.14218358 | D13: 1
B14: Capital Foods FY23 to FY24E growth | C14: =Inputs!$C$9/Inputs!$C$10-1 -> 0.063075833 | D14: =C14/$C$13 -> 0.44362249
B15: Capital Foods FY24E to FY25 growth (first year under TCPL) | C15: =Inputs!$C$11/Inputs!$C$9-1 -> 0.065333333 | D15: =C15/$C$13 -> 0.45949986 | J15: Year 1 under TCPL grew at under half the market rate, well short of the ~2x thesis. FY24 is TCPL's estimate, so treat this as indicative.
B16: Management case: FY25-29 revenue CAGR | C16: =((1+Inputs!D54)*(1+Inputs!E54)*(1+Inputs!F54)*(1+Inputs!G54)*(1+Inputs!H54))^(1/5)-1 -> 0.23381107 | D16: =C16/$C$13 -> 1.6444309
B17: Base case: FY25-29 revenue CAGR | C17: =((1+Inputs!D56)*(1+Inputs!E56)*(1+Inputs!F56)*(1+Inputs!G56)*(1+Inputs!H56))^(1/5)-1 -> 0.14 | D17: =C17/$C$13 -> 0.98464255
B18: Downside case: FY25-29 revenue CAGR | C18: =((1+Inputs!D58)*(1+Inputs!E58)*(1+Inputs!F58)*(1+Inputs!G58)*(1+Inputs!H58))^(1/5)-1 -> 0.086918664 | D18: =C18/$C$13 -> 0.61131296
B20: Competitive position: Capital Foods category rankings, 2022 [1]
B21: Category | C21: Rank | D21: Share
B22: Schezwan chutney | C22: #1 | D22: 0.87 | J22: Category leader in a niche it created; >80% aided awareness across Chinese masala, GGP and sauces [1]. The risk is concentration in a narrow cuisine.
B23: Desi Chinese blended masala | C23: #1 | D23: 0.55
B24: Chinese sauces | C24: #1 | D24: 0.27
B25: Soups | C25: #2 | D25: 0.27
B26: Ginger-garlic paste | C26: #1 | D26: 0.12
B28: Distribution headroom: the core revenue-synergy lever
B29: Capital Foods retail reach (mn outlets) | C29: =Inputs!$C$20 -> 0.4
B30: TCPL retail reach (mn outlets) | C30: =Inputs!$C$21 -> 3.8
B31: TCPL reach as a multiple of Capital Foods | C31: =C30/C29 -> 9.5
B32: Outlet gap (mn) | C32: =C30-C29 -> 3.4
B34: TCPL India channel mix [1]
C35: FY21 | D35: FY22 | E35: FY23
B36: General trade | C36: 0.81 | D36: 0.76 | E36: 0.73
B37: Modern trade and e-commerce | C37: =1-C36 -> 0.19 | D37: =1-D36 -> 0.24 | E37: =1-E36 -> 0.27

Sheet Business Plan & DCF
B2: Business Plan Cases & Standalone DCF of Capital Foods
B3: Three cases; FY25-29 from Inputs, FY30-34 fade linearly to terminal growth with margin held. Rs. crore.
B5: Discount rate
B6: Cost of equity = WACC (Capital Foods is effectively debt-free) | C6: =(Inputs!$C$43+Inputs!$C$44*Inputs!$C$45) -> 0.105
B7: Terminal growth | C7: =Inputs!$C$46 -> 0.055
B9: Management case
B10: Rs. crore | C10: FY24E | D10: FY25 | E10: FY26 | F10: FY27 | G10: FY28 | H10: FY29 | I10: FY30 | J10: FY31 | K10: FY32 | L10: FY33 | M10: FY34
B11: Revenue growth | D11: =Inputs!D$54 -> 0.26 | E11: =Inputs!E$54 -> 0.25 | F11: =Inputs!F$54 -> 0.24 | G11: =Inputs!G$54 -> 0.22 | H11: =Inputs!H$54 -> 0.2 | I11: =H11+($C$7-$H11)/5 -> 0.171 | J11: =I11+($C$7-$H11)/5 -> 0.142 | K11: =J11+($C$7-$H11)/5 -> 0.113 | L11: =K11+($C$7-$H11)/5 -> 0.084 | M11: =L11+($C$7-$H11)/5 -> 0.055
B12: Revenue | C12: =Inputs!$C$9 -> 750 | D12: =C12*(1+D11) -> 945 | E12: =D12*(1+E11) -> 1181.25 | F12: =E12*(1+F11) -> 1464.75 | G12: =F12*(1+G11) -> 1786.995 | H12: =G12*(1+H11) -> 2144.394 | I12: =H12*(1+I11) -> 2511.0854 | J12: =I12*(1+J11) -> 2867.6595 | K12: =J12*(1+K11) -> 3191.705 | ... M12: =L12*(1+M11) -> 3650.0977
B13: EBITDA margin | C13: =Inputs!$C$13 -> 0.2 | D13: =Inputs!D$55 -> 0.21 | E13: =Inputs!E$55 -> 0.215 | F13: =Inputs!F$55 -> 0.22 | G13: =Inputs!G$55 -> 0.225 | H13: =Inputs!H$55 -> 0.23 | I13: =H13 -> 0.23 | J13: =I13 -> 0.23 | K13: =J13 -> 0.23 | L13: =K13 -> 0.23 | M13: =L13 -> 0.23
B14: EBITDA | C14: =C12*C13 -> 150 | D14: =D12*D13 -> 198.45 | E14: =E12*E13 -> 253.96875 | F14: =F12*F13 -> 322.245 | G14: =G12*G13 -> 402.07387 | H14: =H12*H13 -> 493.21062 | I14: =I12*I13 -> 577.54964 | J14: =J12*J13 -> 659.56168 | ... M14: =M12*M13 -> 839.52247
B15: Less: D&A | C15: =-C12*Inputs!$C$47 -> -15 | D15: =-D12*Inputs!$C$47 -> -18.9 | E15: =-E12*Inputs!$C$47 -> -23.625 | F15: =-F12*Inputs!$C$47 -> -29.295 | G15: =-G12*Inputs!$C$47 -> -35.7399 | H15: =-H12*Inputs!$C$47 -> -42.88788 | I15: =-I12*Inputs!$C$47 -> -50.221707 | J15: =-J12*Inputs!$C$47 -> -57.35319 | ... M15: =-M12*Inputs!$C$47 -> -73.001954
B16: EBIT | C16: =C14+C15 -> 135 | D16: =D14+D15 -> 179.55 | E16: =E14+E15 -> 230.34375 | F16: =F14+F15 -> 292.95 | G16: =G14+G15 -> 366.33398 | H16: =H14+H15 -> 450.32274 | I16: =I14+I15 -> 527.32793 | J16: =J14+J15 -> 602.20849 | ... M16: =M14+M15 -> 766.52052
B17: Net income (EBIT x (1 - tax); debt-free) | C17: =C16*(1-Inputs!$C$30) -> 101.25 | D17: =D16*(1-Inputs!$C$30) -> 134.6625 | E17: =E16*(1-Inputs!$C$30) -> 172.75781 | F17: =F16*(1-Inputs!$C$30) -> 219.7125 | G17: =G16*(1-Inputs!$C$30) -> 274.75048 | H17: =H16*(1-Inputs!$C$30) -> 337.74205 | I17: =I16*(1-Inputs!$C$30) -> 395.49595 | J17: =J16*(1-Inputs!$C$30) -> 451.65637 | ... M17: =M16*(1-Inputs!$C$30) -> 574.89039
B18: Free cash flow (NOPAT + D&A - capex - change in NWC) | D18: =D17-D15-D12*Inputs!$C$48-(D12-C12)*Inputs!$C$49 -> 101.8125 | E18: =E17-E15-E12*Inputs!$C$48-(E12-D12)*Inputs!$C$49 -> 132.59531 | F18: =F17-F15-F12*Inputs!$C$48-(F12-E12)*Inputs!$C$49 -> 171.045 | G18: =G17-G15-G12*Inputs!$C$48-(G12-F12)*Inputs!$C$49 -> 218.21113 | H18: =H17-H15-H12*Inputs!$C$48-(H12-G12)*Inputs!$C$49 -> 273.41023 | I18: =I17-I15-I12*Inputs!$C$48-(I12-H12)*Inputs!$C$49 -> 326.38213 | J18: =J17-J15-J12*Inputs!$C$48-(J12-I12)*Inputs!$C$49 -> 380.19088 | K18: =K17-K15-K12*Inputs!$C$48-(K12-J12)*Inputs!$C$49 -> 431.89103 | ... M18: =M17-M15-M12*Inputs!$C$48-(M12-L12)*Inputs!$C$49 -> 515.55468
B19: PV of free cash flow | D19: =D18/(1+$C$6)^1 -> 92.138009 | E19: =E18/(1+$C$6)^2 -> 108.59345 | F19: =F18/(1+$C$6)^3 -> 126.77206 | G19: =G18/(1+$C$6)^4 -> 146.36182 | H19: =H18/(1+$C$6)^5 -> 165.95998 | I19: =I18/(1+$C$6)^6 -> 179.28861 | J19: =J18/(1+$C$6)^7 -> 189.00172 | K19: =K18/(1+$C$6)^8 -> 194.30141 | L19: =L18/(1+$C$6)^9 -> 194.6718 | M19: =M18/(1+$C$6)^10 -> 189.95553
B20: Sum of PV (FY25-34) | C20: =SUM(D19:M19) -> 1587.0444
B21: PV of terminal value | C21: =M18*(1+$C$7)/($C$6-$C$7)/(1+$C$6)^10 -> 4008.0618
B22: Standalone enterprise value | C22: =C20+C21 -> 5595.1061
B23: Implied EV / FY24E sales | C23: =C22/Inputs!$C$9 -> 7.4601415
B24: Standalone value vs. price paid | C24: =C22-Inputs!$C$6 -> 495.10615
B25: FY25 plan revenue vs. FY25 actual | C25: =Inputs!$C$11/D12-1 -> -0.15449735
B27: Base case
B28: Rs. crore | C28: FY24E | D28: FY25 | E28: FY26 | F28: FY27 | G28: FY28 | H28: FY29 | I28: FY30 | J28: FY31 | K28: FY32 | L28: FY33 | M28: FY34
B29: Revenue growth | D29: =Inputs!D$56 -> 0.14 | E29: =Inputs!E$56 -> 0.14 | F29: =Inputs!F$56 -> 0.14 | G29: =Inputs!G$56 -> 0.14 | H29: =Inputs!H$56 -> 0.14 | I29: =H29+($C$7-$H29)/5 -> 0.123 | J29: =I29+($C$7-$H29)/5 -> 0.106 | K29: =J29+($C$7-$H29)/5 -> 0.089 | L29: =K29+($C$7-$H29)/5 -> 0.072 | M29: =L29+($C$7-$H29)/5 -> 0.055
B30: Revenue | C30: =Inputs!$C$9 -> 750 | D30: =C30*(1+D29) -> 855 | E30: =D30*(1+E29) -> 974.7 | F30: =E30*(1+F29) -> 1111.158 | G30: =F30*(1+G29) -> 1266.7201 | H30: =G30*(1+H29) -> 1444.0609 | I30: =H30*(1+I29) -> 1621.6804 | J30: =I30*(1+J29) -> 1793.5786 | K30: =J30*(1+K29) -> 1953.207 | ... M30: =L30*(1+M29) -> 2208.999
B31: EBITDA margin | C31: =Inputs!$C$13 -> 0.2 | D31: =Inputs!D$57 -> 0.2 | E31: =Inputs!E$57 -> 0.2025 | F31: =Inputs!F$57 -> 0.205 | G31: =Inputs!G$57 -> 0.2075 | H31: =Inputs!H$57 -> 0.21 | I31: =H31 -> 0.21 | J31: =I31 -> 0.21 | K31: =J31 -> 0.21 | L31: =K31 -> 0.21 | M31: =L31 -> 0.21
B32: EBITDA | C32: =C30*C31 -> 150 | D32: =D30*D31 -> 171 | E32: =E30*E31 -> 197.37675 | F32: =F30*F31 -> 227.78739 | G32: =G30*G31 -> 262.84442 | H32: =H30*H31 -> 303.2528 | I32: =I30*I31 -> 340.55289 | J32: =J30*J31 -> 376.6515 | ... M32: =M30*M31 -> 463.8898
B33: Less: D&A | C33: =-C30*Inputs!$C$47 -> -15 | D33: =-D30*Inputs!$C$47 -> -17.1 | E33: =-E30*Inputs!$C$47 -> -19.494 | F33: =-F30*Inputs!$C$47 -> -22.22316 | G33: =-G30*Inputs!$C$47 -> -25.334402 | H33: =-H30*Inputs!$C$47 -> -28.881219 | I33: =-I30*Inputs!$C$47 -> -32.433609 | J33: =-J30*Inputs!$C$47 -> -35.871571 | ... M33: =-M30*Inputs!$C$47 -> -44.179981
B34: EBIT | C34: =C32+C33 -> 135 | D34: =D32+D33 -> 153.9 | E34: =E32+E33 -> 177.88275 | F34: =F32+F33 -> 205.56423 | G34: =G32+G33 -> 237.51002 | H34: =H32+H33 -> 274.37158 | I34: =I32+I33 -> 308.11928 | J34: =J32+J33 -> 340.77993 | ... M34: =M32+M33 -> 419.70982
B35: Net income (EBIT x (1 - tax); debt-free) | C35: =C34*(1-Inputs!$C$30) -> 101.25 | D35: =D34*(1-Inputs!$C$30) -> 115.425 | E35: =E34*(1-Inputs!$C$30) -> 133.41206 | F35: =F34*(1-Inputs!$C$30) -> 154.17317 | G35: =G34*(1-Inputs!$C$30) -> 178.13252 | H35: =H34*(1-Inputs!$C$30) -> 205.77868 | I35: =I34*(1-Inputs!$C$30) -> 231.08946 | J35: =J34*(1-Inputs!$C$30) -> 255.58494 | ... M35: =M34*(1-Inputs!$C$30) -> 314.78236
B36: Free cash flow (NOPAT + D&A - capex - change in NWC) | D36: =D35-D33-D30*Inputs!$C$48-(D30-C30)*Inputs!$C$49 -> 94.275 | E36: =E35-E33-E30*Inputs!$C$48-(E30-D30)*Inputs!$C$49 -> 109.30106 | F36: =F35-F33-F30*Inputs!$C$48-(F30-E30)*Inputs!$C$49 -> 126.68663 | G36: =G35-G33-G30*Inputs!$C$48-(G30-F30)*Inputs!$C$49 -> 146.79786 | H36: =H35-H33-H30*Inputs!$C$48-(H30-G30)*Inputs!$C$49 -> 170.05718 | I36: =I35-I33-I30*Inputs!$C$48-(I30-H30)*Inputs!$C$49 -> 193.55832 | J36: =J35-J33-J30*Inputs!$C$48-(J30-I30)*Inputs!$C$49 -> 217.02138 | K36: =K35-K33-K30*Inputs!$C$48-(K30-J30)*Inputs!$C$49 -> 239.64452 | ... M36: =M35-M33-M30*Inputs!$C$48-(M30-L30)*Inputs!$C$49 -> 278.87304
B37: PV of free cash flow | D37: =D36/(1+$C$6)^1 -> 85.316742 | E37: =E36/(1+$C$6)^2 -> 89.515827 | F37: =F36/(1+$C$6)^3 -> 93.895323 | G37: =G36/(1+$C$6)^4 -> 98.462445 | H37: =H36/(1+$C$6)^5 -> 103.22469 | I37: =I36/(1+$C$6)^6 -> 106.32568 | J37: =J36/(1+$C$6)^7 -> 107.88637 | K37: =K36/(1+$C$6)^8 -> 107.81254 | L37: =L36/(1+$C$6)^9 -> 106.08247 | M37: =M36/(1+$C$6)^10 -> 102.75046
B38: Sum of PV (FY25-34) | C38: =SUM(D37:M37) -> 1001.2725
B39: PV of terminal value | C39: =M36*(1+$C$7)/($C$6-$C$7)/(1+$C$6)^10 -> 2168.0346
B40: Standalone enterprise value | C40: =C38+C39 -> 3169.3071
B41: Implied EV / FY24E sales | C41: =C40/Inputs!$C$9 -> 4.2257429
B42: Standalone value vs. price paid | C42: =C40-Inputs!$C$6 -> -1930.6929
B43: FY25 plan revenue vs. FY25 actual | C43: =Inputs!$C$11/D30-1 -> -0.065497076
B45: Downside case
...

Sheet Synergies
B2: Synergy Case: Distribution Expansion and Cost Savings
B3: Built bottom-up from TCPL's stated levers [1][2]. Driver assumptions are on Inputs. Rs. crore.
B5: Rs. crore | C5: FY25 | D5: FY26 | E5: FY27 | F5: FY28 | G5: FY29 | H5: FY30 | I5: FY31 | J5: FY32 | K5: FY33 | L5: FY34
B6: New outlets reached (cumulative, mn) | C6: =Inputs!D$63 -> 0.1 | D6: =Inputs!E$63 -> 0.2 | E6: =Inputs!F$63 -> 0.3 | F6: =Inputs!G$63 -> 0.4 | G6: =Inputs!H$63 -> 0.5 | H6: =G6 -> 0.5 | I6: =H6 -> 0.5 | J6: =I6 -> 0.5 | K6: =J6 -> 0.5 | L6: =K6 -> 0.5
B7: Sales per new outlet (Rs. cr per mn outlets) | C7: =Inputs!$C$9*(1-Inputs!$C$15)/Inputs!$C$20*Inputs!$C$65*(1+Inputs!$C$66) -> 326.8125 | D7: =C7*(1+Inputs!$C$66) -> 343.15312 | E7: =D7*(1+Inputs!$C$66) -> 360.31078 | F7: =E7*(1+Inputs!$C$66) -> 378.32632 | G7: =F7*(1+Inputs!$C$66) -> 397.24264 | H7: =G7*(1+Inputs!$C$66) -> 417.10477 | I7: =H7*(1+Inputs!$C$66) -> 437.96001 | J7: =I7*(1+Inputs!$C$66) -> 459.85801 | K7: =J7*(1+Inputs!$C$66) -> 482.85091 | L7: =K7*(1+Inputs!$C$66) -> 506.99345
B8: Revenue synergy | C8: =C6*C7*Inputs!$C$69 -> 32.68125 | D8: =D6*D7*Inputs!$C$69 -> 68.630625 | E8: =E6*E7*Inputs!$C$69 -> 108.09323 | F8: =F6*F7*Inputs!$C$69 -> 151.33053 | G8: =G6*G7*Inputs!$C$69 -> 198.62132 | H8: =H6*H7*Inputs!$C$69 -> 208.55238 | I8: =I6*I7*Inputs!$C$69 -> 218.98 | J8: =J6*J7*Inputs!$C$69 -> 229.929 | ... L8: =L6*L7*Inputs!$C$69 -> 253.49673
B9: EBITDA from revenue synergy | C9: =C8*Inputs!$C$67 -> 8.1703125 | D9: =D8*Inputs!$C$67 -> 17.157656 | E9: =E8*Inputs!$C$67 -> 27.023309 | F9: =F8*Inputs!$C$67 -> 37.832632 | G9: =G8*Inputs!$C$67 -> 49.65533 | H9: =H8*Inputs!$C$67 -> 52.138096 | I9: =I8*Inputs!$C$67 -> 54.745001 | J9: =J8*Inputs!$C$67 -> 57.482251 | ... L9: =L8*Inputs!$C$67 -> 63.374182
B10: Cost synergies (% of base-case revenue x phase-in) | C10: ='Business Plan & DCF'!D30*Inputs!$C$68*Inputs!D$64*Inputs!$C$69 -> 8.55 | D10: ='Business Plan & DCF'!E30*Inputs!$C$68*Inputs!E$64*Inputs!$C$69 -> 19.494 | E10: ='Business Plan & DCF'!F30*Inputs!$C$68*Inputs!F$64*Inputs!$C$69 -> 22.22316 | F10: ='Business Plan & DCF'!G30*Inputs!$C$68*Inputs!G$64*Inputs!$C$69 -> 25.334402 | G10: ='Business Plan & DCF'!H30*Inputs!$C$68*Inputs!H$64*Inputs!$C$69 -> 28.881219 | H10: ='Business Plan & DCF'!I30*Inputs!$C$68*1*Inputs!$C$69 -> 32.433609 | I10: ='Business Plan & DCF'!J30*Inputs!$C$68*1*Inputs!$C$69 -> 35.871571 | J10: ='Business Plan & DCF'!K30*Inputs!$C$68*1*Inputs!$C$69 -> 39.064141 | K10: ='Business Plan & DCF'!L30*Inputs!$C$68*1*Inputs!$C$69 -> 41.876759 | L10: ='Business Plan & DCF'!M30*Inputs!$C$68*1*Inputs!$C$69 -> 44.179981
B11: Less: one-off integration cost | C11: =-Inputs!$C$40 -> -40
B12: Total synergy EBITDA (net) | C12: =C9+C10+C11 -> -23.279688 | D12: =D9+D10+D11 -> 36.651656 | E12: =E9+E10+E11 -> 49.246469 | F12: =F9+F10+F11 -> 63.167034 | G12: =G9+G10+G11 -> 78.536548 | H12: =H9+H10+H11 -> 84.571705 | I12: =I9+I10+I11 -> 90.616572 | J12: =J9+J10+J11 -> 96.546392 | ... L12: =L9+L10+L11 -> 107.55416
B13: After-tax synergies | C13: =C12*(1-Inputs!$C$30) -> -17.459766 | D13: =D12*(1-Inputs!$C$30) -> 27.488742 | E13: =E12*(1-Inputs!$C$30) -> 36.934851 | F13: =F12*(1-Inputs!$C$30) -> 47.375276 | G13: =G12*(1-Inputs!$C$30) -> 58.902411 | H13: =H12*(1-Inputs!$C$30) -> 63.428778 | I13: =I12*(1-Inputs!$C$30) -> 67.962429 | J13: =J12*(1-Inputs!$C$30) -> 72.409794 | ... L13: =L12*(1-Inputs!$C$30) -> 80.665622
B14: Less: working capital on synergy revenue | C14: =-C8*Inputs!$C$49 -> -3.92175 | D14: =-(D8-C8)*Inputs!$C$49 -> -4.313925 | E14: =-(E8-D8)*Inputs!$C$49 -> -4.7355131 | F14: =-(F8-E8)*Inputs!$C$49 -> -5.1884753 | G14: =-(G8-F8)*Inputs!$C$49 -> -5.6748948 | H14: =-(H8-G8)*Inputs!$C$49 -> -1.1917279 | I14: =-(I8-H8)*Inputs!$C$49 -> -1.2513143 | J14: =-(J8-I8)*Inputs!$C$49 -> -1.31388 | K14: =-(K8-J8)*Inputs!$C$49 -> -1.379574 | L14: =-(L8-K8)*Inputs!$C$49 -> -1.4485527
B15: Synergy cash flow | C15: =C13+C14 -> -21.381516 | D15: =D13+D14 -> 23.174817 | E15: =E13+E14 -> 32.199338 | F15: =F13+F14 -> 42.186801 | G15: =G13+G14 -> 53.227516 | H15: =H13+H14 -> 62.237051 | I15: =I13+I14 -> 66.711115 | J15: =J13+J14 -> 71.095914 | ... L15: =L13+L14 -> 79.217069
B16: PV of synergy cash flow | C16: =C15/(1+'Business Plan & DCF'!$C$6)^1 -> -19.349788 | D16: =D15/(1+'Business Plan & DCF'!$C$6)^2 -> 18.979806 | E16: =E15/(1+'Business Plan & DCF'!$C$6)^3 -> 23.864927 | F16: =F15/(1+'Business Plan & DCF'!$C$6)^4 -> 28.296158 | G16: =G15/(1+'Business Plan & DCF'!$C$6)^5 -> 32.309096 | H16: =H15/(1+'Business Plan & DCF'!$C$6)^6 -> 34.188129 | I16: =I15/(1+'Business Plan & DCF'!$C$6)^7 -> 33.163645 | J16: =J15/(1+'Business Plan & DCF'!$C$6)^8 -> 31.985005 | K16: =K15/(1+'Business Plan & DCF'!$C$6)^9 -> 30.655414 | L16: =L15/(1+'Business Plan & DCF'!$C$6)^10 -> 29.187439
B18: Sum of PV (FY25-34) | C18: =SUM(C16:L16) -> 243.27983
B19: PV of terminal value | C19: =L15*(1+Inputs!$C$46)/('Business Plan & DCF'!$C$6-Inputs!$C$46)/(1+'Business Plan & DCF'!$C$6)^10 -> 615.85496
B20: Value of synergies to TCPL | C20: =C18+C19 -> 859.13479
B21: FY29 revenue synergy as % of base-case FY29 revenue | C21: =G8/'Business Plan & DCF'!H30 -> 0.13754358

Sheet Precedents
B2: Precedent Transactions: Indian Branded FMCG Acquisitions
B3: EV / sales on the revenue basis disclosed at announcement. Rs. crore.
B5: Date | C5: Acquirer | D5: Target (brand) | E5: Category | F5: EV | G5: Revenue | H5: EV / sales | J5: Revenue basis and source
B6: Oct-2022 | C6: Dabur | D6: Badshah Masala | E6: Spices and masalas | F6: 1152 | G6: 250 | H6: =F6/G6 -> 4.608 | J6: FY23E revenue; 51% stake at Rs 1,152 cr EV [8]
B7: Jan-2024 | C7: Tata Consumer | D7: Organic India | E7: Herbal teas, supplements | F7: 1900 | G7: 365 | H7: =F7/G7 -> 5.2054795 | J7: FY24E net sales implied by 5.2x EV/sales [1]
B8: Jan-2025 | C8: HUL | D8: Minimalist | E8: D2C skincare | F8: 2955 | G8: 347 | H8: =F8/G8 -> 8.5158501 | J8: FY24 revenue; Rs 2,955 cr valuation for 90.5% stake [9]
B9: Apr-2025 | C9: ITC | D9: Sresta (24 Mantra) | E9: Organic staples | F9: 472.5 | G9: 306.1 | H9: =F9/G9 -> 1.5436132 | J9: FY24 revenue; cash-free debt-free consideration [10]
G10: 75th percentile | H10: =QUARTILE(H6:H9,3) -> 6.0330721
G11: Median | H11: =MEDIAN(H6:H9) -> 4.9067397
G12: 25th percentile | H12: =QUARTILE(H6:H9,1) -> 3.8419033
B14: Jan-2024 | C14: Tata Consumer | D14: Capital Foods (Ching's) | E14: Sauces, condiments, noodles | F14: =Inputs!$C$6 -> 5100 | G14: =Inputs!$C$9 -> 750 | H14: =F14/G14 -> 6.8 | J14: Subject deal (excluded from the peer statistics); FY24E net revenue [1]
B16: Implied value of Capital Foods (on FY24E net revenue)
F17: 25th pct | G17: Median | H17: 75th pct
B18: Implied EV (Rs. cr) | F18: =H$12*Inputs!$C$9 -> 2881.4275 | G18: =H$11*Inputs!$C$9 -> 3680.0548 | H18: =H$10*Inputs!$C$9 -> 4524.8041
B20: Acquirer's own multiple (what TCPL's shares were priced at)
B21: TCPL market cap / FY24 revenue | F21: =Inputs!$C$27/Inputs!$C$24 -> 6.5763514
B22: TCPL market cap / FY24 EBITDA | F22: =Inputs!$C$27/Inputs!$C$25 -> 43.047783
B23: Price paid / Capital Foods FY24E EBITDA | F23: =Inputs!$C$6/(Inputs!$C$9*Inputs!$C$13) -> 34
B24: Capital Foods valued at TCPL's own EV/sales | F24: =F21*Inputs!$C$9 -> 4932.2636 | J24: Market cap used as a proxy for EV; TCPL's net cash or debt is small relative to Rs 1 lakh cr.

Sheet Accretion
B2: Accretion / Dilution: Impact on TCPL's EPS
B3: Capital Foods only. Case set on Inputs. Checked against TCPL's guidance: 'EPS breakeven in the second year, cash EPS accretive in the first full year' [1].
B5: Funding the Rs 5,100 cr price
B6: Price paid (EV, 100%) | C6: =Inputs!$C$6 -> 5100
B7: Share funded by rights issue equity | C7: =Inputs!$C$36 -> 0.42857143
B8: Equity funding | C8: =C6*C7 -> 2185.7143
B9: New TCPL shares issued at Rs 818 (crore) | C9: =C8/Inputs!$C$34 -> 2.6720224
B10: Debt funding (CP / NCD) | C10: =C6-C8 -> 2914.2857
B11: Annual after-tax interest cost | C11: =C10*Inputs!$C$37*(1-Inputs!$C$30) -> 169.39286
B12: Annual amortisation of intangibles (pre-tax) | C12: =C6*Inputs!$C$38/Inputs!$C$39 -> 51
B14: Pro forma EPS
B15: Rs. crore | D15: FY25 | E15: FY26 | F15: FY27
B16: TCPL standalone net profit | D16: =Inputs!$C$26*(1+Inputs!$C$29)^1 -> 1265.363 | E16: =Inputs!$C$26*(1+Inputs!$C$29)^2 -> 1391.8993 | F16: =Inputs!$C$26*(1+Inputs!$C$29)^3 -> 1531.0892
B17: Capital Foods net income (selected case) | D17: =CHOOSE(Inputs!$C$50,'Business Plan & DCF'!D17,'Business Plan & DCF'!D35,'Business Plan & DCF'!D53) -> 115.425 | E17: =CHOOSE(Inputs!$C$50,'Business Plan & DCF'!E17,'Business Plan & DCF'!E35,'Business Plan & DCF'!E53) -> 133.41206 | F17: =CHOOSE(Inputs!$C$50,'Business Plan & DCF'!F17,'Business Plan & DCF'!F35,'Business Plan & DCF'!F53) -> 154.17317
B18: After-tax synergies (incl. integration cost) | D18: =Synergies!C13 -> -17.459766 | E18: =Synergies!D13 -> 27.488742 | F18: =Synergies!E13 -> 36.934851
B19: Less: after-tax interest on acquisition debt | D19: =-$C$11 -> -169.39286 | E19: =-$C$11 -> -169.39286 | F19: =-$C$11 -> -169.39286
B20: Less: after-tax amortisation | D20: =-$C$12*(1-Inputs!$C$30) -> -38.25 | E20: =-$C$12*(1-Inputs!$C$30) -> -38.25 | F20: =-$C$12*(1-Inputs!$C$30) -> -38.25
B21: Pro forma net profit | D21: =SUM(D16:D20) -> 1155.6854 | E21: =SUM(E16:E20) -> 1345.1572 | F21: =SUM(F16:F20) -> 1514.5544
B23: Standalone shares (crore) | D23: =Inputs!$C$28 -> 95.16 | E23: =Inputs!$C$28 -> 95.16 | F23: =Inputs!$C$28 -> 95.16
B24: Pro forma shares (crore) | D24: =D23+$C$9 -> 97.832022 | E24: =E23+$C$9 -> 97.832022 | F24: =F23+$C$9 -> 97.832022
B26: Standalone EPS (Rs.) | D26: =D16/D23 -> 13.297215 | E26: =E16/E23 -> 14.626937 | F26: =F16/F23 -> 16.08963
B27: Pro forma EPS (Rs.) | D27: =D21/D24 -> 11.812956 | E27: =E21/E24 -> 13.749662 | F27: =F21/F24 -> 15.481172
B28: EPS accretion / (dilution) | D28: =D27/D26-1 -> -0.11162181 | E28: =E27/E26-1 -> -0.05997665 | F28: =F27/F26-1 -> -0.037816785 | H28: Rights shares were issued at a 35% discount, so the equity-funded part of the deal adds shares cheaply relative to TCPL's ~95x P/E.
B29: Cash EPS accretion / (dilution) (adds back amortisation) | D29: =(D21-D20)/D24/D26-1 -> -0.082218938 | E29: =(E21-E20)/E24/E26-1 -> -0.033246769 | F29: =(F21-F20)/F24/F26-1 -> -0.013516893
B30: Result (EPS) | D30: =IF(D28>=0,"Accretive","Dilutive") -> Dilutive | E30: =IF(E28>=0,"Accretive","Dilutive") -> Dilutive | F30: =IF(F28>=0,"Accretive","Dilutive") -> Dilutive
B32: Case in use | C32: =CHOOSE(Inputs!$C$50,"Management","Base","Downside") -> Base

Sheet Sensitivity
B2: Sensitivity Analysis
B3: All cells are live formulas. Base case outlined.
B5: Table 1: Standalone value of Capital Foods (Rs. cr) by FY25-29 revenue growth and EBITDA margin | J5: Compare with the Rs 5,100 cr paid. Growth fades to terminal growth over FY30-34; margin held flat throughout.
B6: Growth (down) / Margin (across) | C6: 0.18 | D6: 0.2 | E6: 0.22 | F6: 0.24
B7: 0.06 | C7: =SensCalc!O5 -> 1687.3514 | D7: =SensCalc!O8 -> 1931.664 | E7: =SensCalc!O11 -> 2175.9765 | F7: =SensCalc!O14 -> 2420.289
B8: 0.1 | C8: =SensCalc!O17 -> 2099.4843 | D8: =SensCalc!O20 -> 2406.4962 | E8: =SensCalc!O23 -> 2713.5082 | F8: =SensCalc!O26 -> 3020.5201
B9: 0.14 | C9: =SensCalc!O29 -> 2607.7722 | D9: =SensCalc!O32 -> 2992.112 | E9: =SensCalc!O35 -> 3376.4518 | F9: =SensCalc!O38 -> 3760.7916
B10: 0.18 | C10: =SensCalc!O41 -> 3231.4148 | D10: =SensCalc!O44 -> 3710.6319 | E10: =SensCalc!O47 -> 4189.849 | F10: =SensCalc!O50 -> 4669.066
B11: 0.22 | C11: =SensCalc!O53 -> 3992.7631 | D11: =SensCalc!O56 -> 4587.8071 | E11: =SensCalc!O59 -> 5182.8512 | F11: =SensCalc!O62 -> 5777.8952
B12: 0.26 | C12: =SensCalc!O65 -> 4917.729 | D12: =SensCalc!O68 -> 5653.4919 | E12: =SensCalc!O71 -> 6389.2547 | F12: =SensCalc!O74 -> 7125.0175
B14: Price paid (Rs. cr) | C14: =Inputs!$C$6 -> 5100
B16: Table 2: Value created / (destroyed) for TCPL (Rs. cr): base-case value + synergies - price paid | J16: Base-case standalone value plus synergies scaled by realisation, minus the EV paid.
B17: Price paid (down) / Synergy realisation (across) | C17: 0 | D17: 0.5 | E17: 1 | F17: 1.5 | G17: 2
B18: 3000 | C18: ='Business Plan & DCF'!$C$40+IF(Inputs!$C$69=0,0,Synergies!$C$20/Inputs!$C$69)*C$17-$B18 -> 169.30714 | D18: ='Business Plan & DCF'!$C$40+IF(Inputs!$C$69=0,0,Synergies!$C$20/Inputs!$C$69)*D$17-$B18 -> 598.87454 | E18: ='Business Plan & DCF'!$C$40+IF(Inputs!$C$69=0,0,Synergies!$C$20/Inputs!$C$69)*E$17-$B18 -> 1028.4419 | F18: ='Business Plan & DCF'!$C$40+IF(Inputs!$C$69=0,0,Synergies!$C$20/Inputs!$C$69)*F$17-$B18 -> 1458.0093 | G18: ='Business Plan & DCF'!$C$40+IF(Inputs!$C$69=0,0,Synergies!$C$20/Inputs!$C$69)*G$17-$B18 -> 1887.5767
B19: 3500 | C19: ='Business Plan & DCF'!$C$40+IF(Inputs!$C$69=0,0,Synergies!$C$20/Inputs!$C$69)*C$17-$B19 -> -330.69286 | D19: ='Business Plan & DCF'!$C$40+IF(Inputs!$C$69=0,0,Synergies!$C$20/Inputs!$C$69)*D$17-$B19 -> 98.874539 | E19: ='Business Plan & DCF'!$C$40+IF(Inputs!$C$69=0,0,Synergies!$C$20/Inputs!$C$69)*E$17-$B19 -> 528.44194 | F19: ='Business Plan & DCF'!$C$40+IF(Inputs!$C$69=0,0,Synergies!$C$20/Inputs!$C$69)*F$17-$B19 -> 958.00933 | G19: ='Business Plan & DCF'!$C$40+IF(Inputs!$C$69=0,0,Synergies!$C$20/Inputs!$C$69)*G$17-$B19 -> 1387.5767
B20: 4000 | C20: ='Business Plan & DCF'!$C$40+IF(Inputs!$C$69=0,0,Synergies!$C$20/Inputs!$C$69)*C$17-$B20 -> -830.69286 | D20: ='Business Plan & DCF'!$C$40+IF(Inputs!$C$69=0,0,Synergies!$C$20/Inputs!$C$69)*D$17-$B20 -> -401.12546 | E20: ='Business Plan & DCF'!$C$40+IF(Inputs!$C$69=0,0,Synergies!$C$20/Inputs!$C$69)*E$17-$B20 -> 28.441936 | F20: ='Business Plan & DCF'!$C$40+IF(Inputs!$C$69=0,0,Synergies!$C$20/Inputs!$C$69)*F$17-$B20 -> 458.00933 | G20: ='Business Plan & DCF'!$C$40+IF(Inputs!$C$69=0,0,Synergies!$C$20/Inputs!$C$69)*G$17-$B20 -> 887.57673
B21: 4500 | C21: ='Business Plan & DCF'!$C$40+IF(Inputs!$C$69=0,0,Synergies!$C$20/Inputs!$C$69)*C$17-$B21 -> -1330.6929 | D21: ='Business Plan & DCF'!$C$40+IF(Inputs!$C$69=0,0,Synergies!$C$20/Inputs!$C$69)*D$17-$B21 -> -901.12546 | E21: ='Business Plan & DCF'!$C$40+IF(Inputs!$C$69=0,0,Synergies!$C$20/Inputs!$C$69)*E$17-$B21 -> -471.55806 | F21: ='Business Plan & DCF'!$C$40+IF(Inputs!$C$69=0,0,Synergies!$C$20/Inputs!$C$69)*F$17-$B21 -> -41.990668 | G21: ='Business Plan & DCF'!$C$40+IF(Inputs!$C$69=0,0,Synergies!$C$20/Inputs!$C$69)*G$17-$B21 -> 387.57673
B22: 5100 | C22: ='Business Plan & DCF'!$C$40+IF(Inputs!$C$69=0,0,Synergies!$C$20/Inputs!$C$69)*C$17-$B22 -> -1930.6929 | D22: ='Business Plan & DCF'!$C$40+IF(Inputs!$C$69=0,0,Synergies!$C$20/Inputs!$C$69)*D$17-$B22 -> -1501.1255 | E22: ='Business Plan & DCF'!$C$40+IF(Inputs!$C$69=0,0,Synergies!$C$20/Inputs!$C$69)*E$17-$B22 -> -1071.5581 | F22: ='Business Plan & DCF'!$C$40+IF(Inputs!$C$69=0,0,Synergies!$C$20/Inputs!$C$69)*F$17-$B22 -> -641.99067 | G22: ='Business Plan & DCF'!$C$40+IF(Inputs!$C$69=0,0,Synergies!$C$20/Inputs!$C$69)*G$17-$B22 -> -212.42327
B23: 5500 | C23: ='Business Plan & DCF'!$C$40+IF(Inputs!$C$69=0,0,Synergies!$C$20/Inputs!$C$69)*C$17-$B23 -> -2330.6929 | D23: ='Business Plan & DCF'!$C$40+IF(Inputs!$C$69=0,0,Synergies!$C$20/Inputs!$C$69)*D$17-$B23 -> -1901.1255 | E23: ='Business Plan & DCF'!$C$40+IF(Inputs!$C$69=0,0,Synergies!$C$20/Inputs!$C$69)*E$17-$B23 -> -1471.5581 | F23: ='Business Plan & DCF'!$C$40+IF(Inputs!$C$69=0,0,Synergies!$C$20/Inputs!$C$69)*F$17-$B23 -> -1041.9907 | G23: ='Business Plan & DCF'!$C$40+IF(Inputs!$C$69=0,0,Synergies!$C$20/Inputs!$C$69)*G$17-$B23 -> -612.42327
B25: Table 3: FY26 EPS accretion / (dilution) by funding mix and debt cost (selected case) | J25: Shows how much the rights issue (equity at Rs 818) versus commercial paper changes the EPS outcome.
B26: Equity share (down) / Debt cost (across) | C26: 0.07 | D26: 0.0775 | E26: 0.085 | F26: 0.09
B27: 0 | C27: =(Accretion!$E$16+Accretion!$E$17+Accretion!$E$18-Inputs!$C$6*(1-$B27)*C$26*(1-Inputs!$C$30)+Accretion!$E$20)/(Inputs!$C$28+Inputs!$C$6*$B27/Inputs!$C$34)/Accretion!$E$26-1 -> -0.10424547 | D27: =(Accretion!$E$16+Accretion!$E$17+Accretion!$E$18-Inputs!$C$6*(1-$B27)*D$26*(1-Inputs!$C$30)+Accretion!$E$20)/(Inputs!$C$28+Inputs!$C$6*$B27/Inputs!$C$34)/Accretion!$E$26-1 -> -0.1248558 | E27: =(Accretion!$E$16+Accretion!$E$17+Accretion!$E$18-Inputs!$C$6*(1-$B27)*E$26*(1-Inputs!$C$30)+Accretion!$E$20)/(Inputs!$C$28+Inputs!$C$6*$B27/Inputs!$C$34)/Accretion!$E$26-1 -> -0.14546612 | F27: =(Accretion!$E$16+Accretion!$E$17+Accretion!$E$18-Inputs!$C$6*(1-$B27)*F$26*(1-Inputs!$C$30)+Accretion!$E$20)/(Inputs!$C$28+Inputs!$C$6*$B27/Inputs!$C$34)/Accretion!$E$26-1 -> -0.15920634
B28: 0.25 | C28: =(Accretion!$E$16+Accretion!$E$17+Accretion!$E$18-Inputs!$C$6*(1-$B28)*C$26*(1-Inputs!$C$30)+Accretion!$E$20)/(Inputs!$C$28+Inputs!$C$6*$B28/Inputs!$C$34)/Accretion!$E$26-1 -> -0.07136534 | D28: =(Accretion!$E$16+Accretion!$E$17+Accretion!$E$18-Inputs!$C$6*(1-$B28)*D$26*(1-Inputs!$C$30)+Accretion!$E$20)/(Inputs!$C$28+Inputs!$C$6*$B28/Inputs!$C$34)/Accretion!$E$26-1 -> -0.086573975 | E28: =(Accretion!$E$16+Accretion!$E$17+Accretion!$E$18-Inputs!$C$6*(1-$B28)*E$26*(1-Inputs!$C$30)+Accretion!$E$20)/(Inputs!$C$28+Inputs!$C$6*$B28/Inputs!$C$34)/Accretion!$E$26-1 -> -0.10178261 | F28: =(Accretion!$E$16+Accretion!$E$17+Accretion!$E$18-Inputs!$C$6*(1-$B28)*F$26*(1-Inputs!$C$30)+Accretion!$E$20)/(Inputs!$C$28+Inputs!$C$6*$B28/Inputs!$C$34)/Accretion!$E$26-1 -> -0.1119217
B29: 0.43 | C29: =(Accretion!$E$16+Accretion!$E$17+Accretion!$E$18-Inputs!$C$6*(1-$B29)*C$26*(1-Inputs!$C$30)+Accretion!$E$20)/(Inputs!$C$28+Inputs!$C$6*$B29/Inputs!$C$34)/Accretion!$E$26-1 -> -0.048340328 | D29: =(Accretion!$E$16+Accretion!$E$17+Accretion!$E$18-Inputs!$C$6*(1-$B29)*D$26*(1-Inputs!$C$30)+Accretion!$E$20)/(Inputs!$C$28+Inputs!$C$6*$B29/Inputs!$C$34)/Accretion!$E$26-1 -> -0.059766312 | E29: =(Accretion!$E$16+Accretion!$E$17+Accretion!$E$18-Inputs!$C$6*(1-$B29)*E$26*(1-Inputs!$C$30)+Accretion!$E$20)/(Inputs!$C$28+Inputs!$C$6*$B29/Inputs!$C$34)/Accretion!$E$26-1 -> -0.071192296 | F29: =(Accretion!$E$16+Accretion!$E$17+Accretion!$E$18-Inputs!$C$6*(1-$B29)*F$26*(1-Inputs!$C$30)+Accretion!$E$20)/(Inputs!$C$28+Inputs!$C$6*$B29/Inputs!$C$34)/Accretion!$E$26-1 -> -0.078809618
B30: 0.6 | C30: =(Accretion!$E$16+Accretion!$E$17+Accretion!$E$18-Inputs!$C$6*(1-$B30)*C$26*(1-Inputs!$C$30)+Accretion!$E$20)/(Inputs!$C$28+Inputs!$C$6*$B30/Inputs!$C$34)/Accretion!$E$26-1 -> -0.027074284 | D30: =(Accretion!$E$16+Accretion!$E$17+Accretion!$E$18-Inputs!$C$6*(1-$B30)*D$26*(1-Inputs!$C$30)+Accretion!$E$20)/(Inputs!$C$28+Inputs!$C$6*$B30/Inputs!$C$34)/Accretion!$E$26-1 -> -0.035006588 | E30: =(Accretion!$E$16+Accretion!$E$17+Accretion!$E$18-Inputs!$C$6*(1-$B30)*E$26*(1-Inputs!$C$30)+Accretion!$E$20)/(Inputs!$C$28+Inputs!$C$6*$B30/Inputs!$C$34)/Accretion!$E$26-1 -> -0.042938893 | F30: =(Accretion!$E$16+Accretion!$E$17+Accretion!$E$18-Inputs!$C$6*(1-$B30)*F$26*(1-Inputs!$C$30)+Accretion!$E$20)/(Inputs!$C$28+Inputs!$C$6*$B30/Inputs!$C$34)/Accretion!$E$26-1 -> -0.048227096
B31: 1 | C31: =(Accretion!$E$16+Accretion!$E$17+Accretion!$E$18-Inputs!$C$6*(1-$B31)*C$26*(1-Inputs!$C$30)+Accretion!$E$20)/(Inputs!$C$28+Inputs!$C$6*$B31/Inputs!$C$34)/Accretion!$E$26-1 -> 0.02120969 | D31: =(Accretion!$E$16+Accretion!$E$17+Accretion!$E$18-Inputs!$C$6*(1-$B31)*D$26*(1-Inputs!$C$30)+Accretion!$E$20)/(Inputs!$C$28+Inputs!$C$6*$B31/Inputs!$C$34)/Accretion!$E$26-1 -> 0.02120969 | E31: =(Accretion!$E$16+Accretion!$E$17+Accretion!$E$18-Inputs!$C$6*(1-$B31)*E$26*(1-Inputs!$C$30)+Accretion!$E$20)/(Inputs!$C$28+Inputs!$C$6*$B31/Inputs!$C$34)/Accretion!$E$26-1 -> 0.02120969 | F31: =(Accretion!$E$16+Accretion!$E$17+Accretion!$E$18-Inputs!$C$6*(1-$B31)*F$26*(1-Inputs!$C$30)+Accretion!$E$20)/(Inputs!$C$28+Inputs!$C$6*$B31/Inputs!$C$34)/Accretion!$E$26-1 -> 0.02120969

Sheet Football Field
B2: Valuation Summary: What is Capital Foods worth? (EV, Rs. cr)
B3: Ranges from each lens against the Rs 5,100 cr paid.
B5: Method | C5: Low | D5: High | E5: Spread
B6: DCF standalone: downside to management case | C6: ='Business Plan & DCF'!C58 -> 2274.4522 | D6: ='Business Plan & DCF'!C22 -> 5595.1061 | E6: =D6-C6 -> 3320.6539 | G6: Point estimates are shown as thin bars (+/-0.5%) so they appear on the chart.
B7: DCF base case + synergies (0-100% realisation) | C7: ='Business Plan & DCF'!C40 -> 3169.3071 | D7: ='Business Plan & DCF'!C40+Synergies!C20 -> 4028.4419 | E7: =D7-C7 -> 859.13479
B8: Precedent transactions (25th-75th pct EV/sales) | C8: =Precedents!F18 -> 2881.4275 | D8: =Precedents!H18 -> 4524.8041 | E8: =D8-C8 -> 1643.3766
B9: TCPL's own EV/sales applied (point) | C9: =Precedents!F24*0.995 -> 4907.6023 | D9: =Precedents!F24*1.005 -> 4956.9249 | E9: =D9-C9 -> 49.322636
B10: Price paid (point) | C10: =Inputs!$C$6*0.995 -> 5074.5 | D10: =Inputs!$C$6*1.005 -> 5125.5 | E10: =D10-C10 -> 51

Sheet Sources
B2: Sources
B3: Primary and press sources used for every hardcoded fact. Accessed October 2026.
B5: # | C5: Source | D5: URL
B6: [1] | C6: TCPL acquisition investor presentation, 12 Jan 2024 (NSE filing) | D6: https://nsearchives.nseindia.com/corporate/TATACONSUM_12012024224028_TCPL_Acquisition_Investor_presentation_sd.pdf
B7: [2] | C7: PTI via The Week: TCPL to acquire Capital Foods, Organic India (12 Jan 2024) | D7: https://www.theweek.in/wire-updates/business/2024/01/12/del94-biz-ld-tcpl-acqusition.html
B8: [3] | C8: Business Today: TCPL board approves Rs 6,500 cr fundraise (19 Jan 2024) | D8: https://www.businesstoday.in/amp/latest/corporate/story/tata-consumer-to-raise-rs-6500-crore-to-fund-acquistion-of-capital-foods-organic-india-414063-2024-01-19
B9: [4] | C9: Bajaj Broking: TCPL Rs 3,000 cr rights issue at Rs 818 (Jul 2024) | D9: https://bajajbroking.in/blog/tata-consumer-products-announces-rs3000-cr-rights-issue-at--818share
B10: [5] | C10: TCPL press release: results for year ended 31 Mar 2024 | D10: https://www.tataconsumer.com/news/results-quarter-and-year-ended-31st-march-2024
B11: [6] | C11: Business Standard: TCPL FY24 consolidated net profit (23 Apr 2024) | D11: https://www.business-standard.com/amp/markets/capital-market-news/tata-consumer-products-consolidated-net-profit-declines-19-35-in-the-march-2024-quarter-124042300875_1.html
B12: [7] | C12: PTI via The Week: Capital Foods, Organic India FY25 performance (26 May 2025) | D12: https://www.theweek.in/wire-updates/business/2025/05/26/dcm100-biz-tata-consumer-products.html
B13: [8] | C13: Business Today: Dabur acquires 51% of Badshah Masala (Oct 2022) | D13: https://www.businesstoday.in/amp/latest/corporate/story/daburs-got-its-badshah-on-board-acquires-majority-stake-in-the-prominent-masala-brand-350870-2022-10-26
B14: [9] | C14: Entrackr: HUL acquires 90.5% of Minimalist (Jan 2025) | D14: https://entrackr.com/news/hul-acquires-905-stake-in-minimalist-at-rs-2955-cr-valuation-8644087
B15: [10] | C15: Outlook Business: ITC to acquire Sresta Natural / 24 Mantra Organic (Apr 2025) | D15: https://www.outlookbusiness.com/corporate/itc-to-acquire-24-mantra-organic-brand-for-rs-47250-crore-735-remaining-stake-in-mother-sparsh

Sheet SensCalc
B2: Helper: DCF engine for Sensitivity Table 1 (do not edit)
B3: One block per growth / margin pair.
B4: Growth | C4: Margin | D4: FY24E | E4: FY25 | F4: FY26 | G4: FY27 | H4: FY28 | I4: FY29 | J4: FY30 | K4: FY31 | L4: FY32 | M4: FY33 | N4: FY34 | O4: EV
B5: =Sensitivity!$B$7 -> 0.06 | C5: =Sensitivity!$C$6 -> 0.18 | D5: =Inputs!$C$9 -> 750 | E5: =D5*(1+E6) -> 795 | F5: =E5*(1+F6) -> 842.7 | G5: =F5*(1+G6) -> 893.262 | H5: =G5*(1+H6) -> 946.85772 | I5: =H5*(1+I6) -> 1003.6692 | J5: =I5*(1+J6) -> 1062.8857 | K5: =J5*(1+K6) -> 1124.533 | L5: =K5*(1+L6) -> 1188.6314 | ... N5: =M5*(1+N6) -> 1324.2305 | O5: =E7/(1+'Business Plan & DCF'!$C$6)^1+F7/(1+'Business Plan & DCF'!$C$6)^2+G7/(1+'Business Plan & DCF'!$C$6)^3+H7/(1+'Business Plan & DCF'!$C$6)^4+I7/(1+'Business Plan & DCF'!$C$6)^5+J7/(1+'Business Plan & DCF'!$C$6)^6+K7/(1+'Business Plan & DCF'!$C$6)^7+L7/(1+'Business Plan & DCF'!$C$6)^8+M7/(1+'Business Plan & DCF'!$C$6)^9+N7/(1+'Business Plan & DCF'!$C$6)^10+N7*(1+'Business Plan & DCF'!$C$7)/('Business Plan & DCF'!$C$6-'Business Plan & DCF'!$C$7)/(1+'Business Plan & DCF'!$C$6)^10 -> 1687.3514
E6: =$B$5 -> 0.06 | F6: =$B$5 -> 0.06 | G6: =$B$5 -> 0.06 | H6: =$B$5 -> 0.06 | I6: =$B$5 -> 0.06 | J6: =I6+('Business Plan & DCF'!$C$7-$B$5)/5 -> 0.059 | K6: =J6+('Business Plan & DCF'!$C$7-$B$5)/5 -> 0.058 | L6: =K6+('Business Plan & DCF'!$C$7-$B$5)/5 -> 0.057 | M6: =L6+('Business Plan & DCF'!$C$7-$B$5)/5 -> 0.056 | N6: =M6+('Business Plan & DCF'!$C$7-$B$5)/5 -> 0.055
E7: =(E5*$C$5-E5*Inputs!$C$47)*(1-Inputs!$C$30)+E5*Inputs!$C$47-E5*Inputs!$C$48-(E5-D5)*Inputs!$C$49 -> 82.05 | F7: =(F5*$C$5-F5*Inputs!$C$47)*(1-Inputs!$C$30)+F5*Inputs!$C$47-F5*Inputs!$C$48-(F5-E5)*Inputs!$C$49 -> 86.973 | G7: =(G5*$C$5-G5*Inputs!$C$47)*(1-Inputs!$C$30)+G5*Inputs!$C$47-G5*Inputs!$C$48-(G5-F5)*Inputs!$C$49 -> 92.19138 | H7: =(H5*$C$5-H5*Inputs!$C$47)*(1-Inputs!$C$30)+H5*Inputs!$C$47-H5*Inputs!$C$48-(H5-G5)*Inputs!$C$49 -> 97.722863 | I7: =(I5*$C$5-I5*Inputs!$C$47)*(1-Inputs!$C$30)+I5*Inputs!$C$47-I5*Inputs!$C$48-(I5-H5)*Inputs!$C$49 -> 103.58623 | J7: =(J5*$C$5-J5*Inputs!$C$47)*(1-Inputs!$C$30)+J5*Inputs!$C$47-J5*Inputs!$C$48-(J5-I5)*Inputs!$C$49 -> 109.81145 | K7: =(K5*$C$5-K5*Inputs!$C$47)*(1-Inputs!$C$30)+K5*Inputs!$C$47-K5*Inputs!$C$48-(K5-J5)*Inputs!$C$49 -> 116.30095 | L7: =(L5*$C$5-L5*Inputs!$C$47)*(1-Inputs!$C$30)+L5*Inputs!$C$47-L5*Inputs!$C$48-(L5-K5)*Inputs!$C$49 -> 123.05765 | ... N7: =(N5*$C$5-N5*Inputs!$C$47)*(1-Inputs!$C$30)+N5*Inputs!$C$47-N5*Inputs!$C$48-(N5-M5)*Inputs!$C$49 -> 137.38107
B8: =Sensitivity!$B$7 -> 0.06 | C8: =Sensitivity!$D$6 -> 0.2 | D8: =Inputs!$C$9 -> 750 | E8: =D8*(1+E9) -> 795 | F8: =E8*(1+F9) -> 842.7 | G8: =F8*(1+G9) -> 893.262 | H8: =G8*(1+H9) -> 946.85772 | I8: =H8*(1+I9) -> 1003.6692 | J8: =I8*(1+J9) -> 1062.8857 | K8: =J8*(1+K9) -> 1124.533 | L8: =K8*(1+L9) -> 1188.6314 | ... N8: =M8*(1+N9) -> 1324.2305 | O8: =E10/(1+'Business Plan & DCF'!$C$6)^1+F10/(1+'Business Plan & DCF'!$C$6)^2+G10/(1+'Business Plan & DCF'!$C$6)^3+H10/(1+'Business Plan & DCF'!$C$6)^4+I10/(1+'Business Plan & DCF'!$C$6)^5+J10/(1+'Business Plan & DCF'!$C$6)^6+K10/(1+'Business Plan & DCF'!$C$6)^7+L10/(1+'Business Plan & DCF'!$C$6)^8+M10/(1+'Business Plan & DCF'!$C$6)^9+N10/(1+'Business Plan & DCF'!$C$6)^10+N10*(1+'Business Plan & DCF'!$C$7)/('Business Plan & DCF'!$C$6-'Business Plan & DCF'!$C$7)/(1+'Business Plan & DCF'!$C$6)^10 -> 1931.664
E9: =$B$8 -> 0.06 | F9: =$B$8 -> 0.06 | G9: =$B$8 -> 0.06 | H9: =$B$8 -> 0.06 | I9: =$B$8 -> 0.06 | J9: =I9+('Business Plan & DCF'!$C$7-$B$8)/5 -> 0.059 | K9: =J9+('Business Plan & DCF'!$C$7-$B$8)/5 -> 0.058 | L9: =K9+('Business Plan & DCF'!$C$7-$B$8)/5 -> 0.057 | M9: =L9+('Business Plan & DCF'!$C$7-$B$8)/5 -> 0.056 | N9: =M9+('Business Plan & DCF'!$C$7-$B$8)/5 -> 0.055
E10: =(E8*$C$8-E8*Inputs!$C$47)*(1-Inputs!$C$30)+E8*Inputs!$C$47-E8*Inputs!$C$48-(E8-D8)*Inputs!$C$49 -> 93.975 | F10: =(F8*$C$8-F8*Inputs!$C$47)*(1-Inputs!$C$30)+F8*Inputs!$C$47-F8*Inputs!$C$48-(F8-E8)*Inputs!$C$49 -> 99.6135 | G10: =(G8*$C$8-G8*Inputs!$C$47)*(1-Inputs!$C$30)+G8*Inputs!$C$47-G8*Inputs!$C$48-(G8-F8)*Inputs!$C$49 -> 105.59031 | H10: =(H8*$C$8-H8*Inputs!$C$47)*(1-Inputs!$C$30)+H8*Inputs!$C$47-H8*Inputs!$C$48-(H8-G8)*Inputs!$C$49 -> 111.92573 | I10: =(I8*$C$8-I8*Inputs!$C$47)*(1-Inputs!$C$30)+I8*Inputs!$C$47-I8*Inputs!$C$48-(I8-H8)*Inputs!$C$49 -> 118.64127 | J10: =(J8*$C$8-J8*Inputs!$C$47)*(1-Inputs!$C$30)+J8*Inputs!$C$47-J8*Inputs!$C$48-(J8-I8)*Inputs!$C$49 -> 125.75473 | K10: =(K8*$C$8-K8*Inputs!$C$47)*(1-Inputs!$C$30)+K8*Inputs!$C$47-K8*Inputs!$C$48-(K8-J8)*Inputs!$C$49 -> 133.16894 | L10: =(L8*$C$8-L8*Inputs!$C$47)*(1-Inputs!$C$30)+L8*Inputs!$C$47-L8*Inputs!$C$48-(L8-K8)*Inputs!$C$49 -> 140.88712 | ... N10: =(N8*$C$8-N8*Inputs!$C$47)*(1-Inputs!$C$30)+N8*Inputs!$C$47-N8*Inputs!$C$48-(N8-M8)*Inputs!$C$49 -> 157.24453
B11: =Sensitivity!$B$7 -> 0.06 | C11: =Sensitivity!$E$6 -> 0.22 | D11: =Inputs!$C$9 -> 750 | E11: =D11*(1+E12) -> 795 | F11: =E11*(1+F12) -> 842.7 | G11: =F11*(1+G12) -> 893.262 | H11: =G11*(1+H12) -> 946.85772 | I11: =H11*(1+I12) -> 1003.6692 | J11: =I11*(1+J12) -> 1062.8857 | K11: =J11*(1+K12) -> 1124.533 | L11: =K11*(1+L12) -> 1188.6314 | ... N11: =M11*(1+N12) -> 1324.2305 | O11: =E13/(1+'Business Plan & DCF'!$C$6)^1+F13/(1+'Business Plan & DCF'!$C$6)^2+G13/(1+'Business Plan & DCF'!$C$6)^3+H13/(1+'Business Plan & DCF'!$C$6)^4+I13/(1+'Business Plan & DCF'!$C$6)^5+J13/(1+'Business Plan & DCF'!$C$6)^6+K13/(1+'Business Plan & DCF'!$C$6)^7+L13/(1+'Business Plan & DCF'!$C$6)^8+M13/(1+'Business Plan & DCF'!$C$6)^9+N13/(1+'Business Plan & DCF'!$C$6)^10+N13*(1+'Business Plan & DCF'!$C$7)/('Business Plan & DCF'!$C$6-'Business Plan & DCF'!$C$7)/(1+'Business Plan & DCF'!$C$6)^10 -> 2175.9765
E12: =$B$11 -> 0.06 | F12: =$B$11 -> 0.06 | G12: =$B$11 -> 0.06 | H12: =$B$11 -> 0.06 | I12: =$B$11 -> 0.06 | J12: =I12+('Business Plan & DCF'!$C$7-$B$11)/5 -> 0.059 | K12: =J12+('Business Plan & DCF'!$C$7-$B$11)/5 -> 0.058 | L12: =K12+('Business Plan & DCF'!$C$7-$B$11)/5 -> 0.057 | M12: =L12+('Business Plan & DCF'!$C$7-$B$11)/5 -> 0.056 | N12: =M12+('Business Plan & DCF'!$C$7-$B$11)/5 -> 0.055
E13: =(E11*$C$11-E11*Inputs!$C$47)*(1-Inputs!$C$30)+E11*Inputs!$C$47-E11*Inputs!$C$48-(E11-D11)*Inputs!$C$49 -> 105.9 | F13: =(F11*$C$11-F11*Inputs!$C$47)*(1-Inputs!$C$30)+F11*Inputs!$C$47-F11*Inputs!$C$48-(F11-E11)*Inputs!$C$49 -> 112.254 | G13: =(G11*$C$11-G11*Inputs!$C$47)*(1-Inputs!$C$30)+G11*Inputs!$C$47-G11*Inputs!$C$48-(G11-F11)*Inputs!$C$49 -> 118.98924 | H13: =(H11*$C$11-H11*Inputs!$C$47)*(1-Inputs!$C$30)+H11*Inputs!$C$47-H11*Inputs!$C$48-(H11-G11)*Inputs!$C$49 -> 126.12859 | I13: =(I11*$C$11-I11*Inputs!$C$47)*(1-Inputs!$C$30)+I11*Inputs!$C$47-I11*Inputs!$C$48-(I11-H11)*Inputs!$C$49 -> 133.69631 | J13: =(J11*$C$11-J11*Inputs!$C$47)*(1-Inputs!$C$30)+J11*Inputs!$C$47-J11*Inputs!$C$48-(J11-I11)*Inputs!$C$49 -> 141.69802 | K13: =(K11*$C$11-K11*Inputs!$C$47)*(1-Inputs!$C$30)+K11*Inputs!$C$47-K11*Inputs!$C$48-(K11-J11)*Inputs!$C$49 -> 150.03694 | L13: =(L11*$C$11-L11*Inputs!$C$47)*(1-Inputs!$C$30)+L11*Inputs!$C$47-L11*Inputs!$C$48-(L11-K11)*Inputs!$C$49 -> 158.71659 | ... N13: =(N11*$C$11-N11*Inputs!$C$47)*(1-Inputs!$C$30)+N11*Inputs!$C$47-N11*Inputs!$C$48-(N11-M11)*Inputs!$C$49 -> 177.10798
B14: =Sensitivity!$B$7 -> 0.06 | C14: =Sensitivity!$F$6 -> 0.24 | D14: =Inputs!$C$9 -> 750 | E14: =D14*(1+E15) -> 795 | F14: =E14*(1+F15) -> 842.7 | G14: =F14*(1+G15) -> 893.262 | H14: =G14*(1+H15) -> 946.85772 | I14: =H14*(1+I15) -> 1003.6692 | J14: =I14*(1+J15) -> 1062.8857 | K14: =J14*(1+K15) -> 1124.533 | L14: =K14*(1+L15) -> 1188.6314 | ... N14: =M14*(1+N15) -> 1324.2305 | O14: =E16/(1+'Business Plan & DCF'!$C$6)^1+F16/(1+'Business Plan & DCF'!$C$6)^2+G16/(1+'Business Plan & DCF'!$C$6)^3+H16/(1+'Business Plan & DCF'!$C$6)^4+I16/(1+'Business Plan & DCF'!$C$6)^5+J16/(1+'Business Plan & DCF'!$C$6)^6+K16/(1+'Business Plan & DCF'!$C$6)^7+L16/(1+'Business Plan & DCF'!$C$6)^8+M16/(1+'Business Plan & DCF'!$C$6)^9+N16/(1+'Business Plan & DCF'!$C$6)^10+N16*(1+'Business Plan & DCF'!$C$7)/('Business Plan & DCF'!$C$6-'Business Plan & DCF'!$C$7)/(1+'Business Plan & DCF'!$C$6)^10 -> 2420.289
E15: =$B$14 -> 0.06 | F15: =$B$14 -> 0.06 | G15: =$B$14 -> 0.06 | H15: =$B$14 -> 0.06 | I15: =$B$14 -> 0.06 | J15: =I15+('Business Plan & DCF'!$C$7-$B$14)/5 -> 0.059 | K15: =J15+('Business Plan & DCF'!$C$7-$B$14)/5 -> 0.058 | L15: =K15+('Business Plan & DCF'!$C$7-$B$14)/5 -> 0.057 | M15: =L15+('Business Plan & DCF'!$C$7-$B$14)/5 -> 0.056 | N15: =M15+('Business Plan & DCF'!$C$7-$B$14)/5 -> 0.055
E16: =(E14*$C$14-E14*Inputs!$C$47)*(1-Inputs!$C$30)+E14*Inputs!$C$47-E14*Inputs!$C$48-(E14-D14)*Inputs!$C$49 -> 117.825 | F16: =(F14*$C$14-F14*Inputs!$C$47)*(1-Inputs!$C$30)+F14*Inputs!$C$47-F14*Inputs!$C$48-(F14-E14)*Inputs!$C$49 -> 124.8945 | G16: =(G14*$C$14-G14*Inputs!$C$47)*(1-Inputs!$C$30)+G14*Inputs!$C$47-G14*Inputs!$C$48-(G14-F14)*Inputs!$C$49 -> 132.38817 | H16: =(H14*$C$14-H14*Inputs!$C$47)*(1-Inputs!$C$30)+H14*Inputs!$C$47-H14*Inputs!$C$48-(H14-G14)*Inputs!$C$49 -> 140.33146 | I16: =(I14*$C$14-I14*Inputs!$C$47)*(1-Inputs!$C$30)+I14*Inputs!$C$47-I14*Inputs!$C$48-(I14-H14)*Inputs!$C$49 -> 148.75135 | J16: =(J14*$C$14-J14*Inputs!$C$47)*(1-Inputs!$C$30)+J14*Inputs!$C$47-J14*Inputs!$C$48-(J14-I14)*Inputs!$C$49 -> 157.6413 | K16: =(K14*$C$14-K14*Inputs!$C$47)*(1-Inputs!$C$30)+K14*Inputs!$C$47-K14*Inputs!$C$48-(K14-J14)*Inputs!$C$49 -> 166.90494 | L16: =(L14*$C$14-L14*Inputs!$C$47)*(1-Inputs!$C$30)+L14*Inputs!$C$47-L14*Inputs!$C$48-(L14-K14)*Inputs!$C$49 -> 176.54606 | ... N16: =(N14*$C$14-N14*Inputs!$C$47)*(1-Inputs!$C$30)+N14*Inputs!$C$47-N14*Inputs!$C$48-(N14-M14)*Inputs!$C$49 -> 196.97144
B17: =Sensitivity!$B$8 -> 0.1 | C17: =Sensitivity!$C$6 -> 0.18 | D17: =Inputs!$C$9 -> 750 | E17: =D17*(1+E18) -> 825 | F17: =E17*(1+F18) -> 907.5 | G17: =F17*(1+G18) -> 998.25 | H17: =G17*(1+H18) -> 1098.075 | I17: =H17*(1+I18) -> 1207.8825 | J17: =I17*(1+J18) -> 1317.7998 | K17: =J17*(1+K18) -> 1425.8594 | L17: =K17*(1+L18) -> 1529.9471 | ... N17: =M17*(1+N18) -> 1717.3962 | O17: =E19/(1+'Business Plan & DCF'!$C$6)^1+F19/(1+'Business Plan & DCF'!$C$6)^2+G19/(1+'Business Plan & DCF'!$C$6)^3+H19/(1+'Business Plan & DCF'!$C$6)^4+I19/(1+'Business Plan & DCF'!$C$6)^5+J19/(1+'Business Plan & DCF'!$C$6)^6+K19/(1+'Business Plan & DCF'!$C$6)^7+L19/(1+'Business Plan & DCF'!$C$6)^8+M19/(1+'Business Plan & DCF'!$C$6)^9+N19/(1+'Business Plan & DCF'!$C$6)^10+N19*(1+'Business Plan & DCF'!$C$7)/('Business Plan & DCF'!$C$6-'Business Plan & DCF'!$C$7)/(1+'Business Plan & DCF'!$C$6)^10 -> 2099.4843
E18: =$B$17 -> 0.1 | F18: =$B$17 -> 0.1 | G18: =$B$17 -> 0.1 | H18: =$B$17 -> 0.1 | I18: =$B$17 -> 0.1 | J18: =I18+('Business Plan & DCF'!$C$7-$B$17)/5 -> 0.091 | K18: =J18+('Business Plan & DCF'!$C$7-$B$17)/5 -> 0.082 | L18: =K18+('Business Plan & DCF'!$C$7-$B$17)/5 -> 0.073 | M18: =L18+('Business Plan & DCF'!$C$7-$B$17)/5 -> 0.064 | N18: =M18+('Business Plan & DCF'!$C$7-$B$17)/5 -> 0.055
E19: =(E17*$C$17-E17*Inputs!$C$47)*(1-Inputs!$C$30)+E17*Inputs!$C$47-E17*Inputs!$C$48-(E17-D17)*Inputs!$C$49 -> 81.75 | F19: =(F17*$C$17-F17*Inputs!$C$47)*(1-Inputs!$C$30)+F17*Inputs!$C$47-F17*Inputs!$C$48-(F17-E17)*Inputs!$C$49 -> 89.925 | G19: =(G17*$C$17-G17*Inputs!$C$47)*(1-Inputs!$C$30)+G17*Inputs!$C$47-G17*Inputs!$C$48-(G17-F17)*Inputs!$C$49 -> 98.9175 | H19: =(H17*$C$17-H17*Inputs!$C$47)*(1-Inputs!$C$30)+H17*Inputs!$C$47-H17*Inputs!$C$48-(H17-G17)*Inputs!$C$49 -> 108.80925 | I19: =(I17*$C$17-I17*Inputs!$C$47)*(1-Inputs!$C$30)+I17*Inputs!$C$47-I17*Inputs!$C$48-(I17-H17)*Inputs!$C$49 -> 119.69018 | J19: =(J17*$C$17-J17*Inputs!$C$47)*(1-Inputs!$C$30)+J17*Inputs!$C$47-J17*Inputs!$C$48-(J17-I17)*Inputs!$C$49 -> 131.7679 | K19: =(K17*$C$17-K17*Inputs!$C$47)*(1-Inputs!$C$30)+K17*Inputs!$C$47-K17*Inputs!$C$48-(K17-J17)*Inputs!$C$49 -> 143.87738 | L19: =(L17*$C$17-L17*Inputs!$C$47)*(1-Inputs!$C$30)+L17*Inputs!$C$47-L17*Inputs!$C$48-(L17-K17)*Inputs!$C$49 -> 155.80366 | ... N19: =(N17*$C$17-N17*Inputs!$C$47)*(1-Inputs!$C$30)+N17*Inputs!$C$47-N17*Inputs!$C$48-(N17-M17)*Inputs!$C$49 -> 178.16969
B20: =Sensitivity!$B$8 -> 0.1 | C20: =Sensitivity!$D$6 -> 0.2 | D20: =Inputs!$C$9 -> 750 | E20: =D20*(1+E21) -> 825 | F20: =E20*(1+F21) -> 907.5 | G20: =F20*(1+G21) -> 998.25 | H20: =G20*(1+H21) -> 1098.075 | I20: =H20*(1+I21) -> 1207.8825 | J20: =I20*(1+J21) -> 1317.7998 | K20: =J20*(1+K21) -> 1425.8594 | L20: =K20*(1+L21) -> 1529.9471 | ... N20: =M20*(1+N21) -> 1717.3962 | O20: =E22/(1+'Business Plan & DCF'!$C$6)^1+F22/(1+'Business Plan & DCF'!$C$6)^2+G22/(1+'Business Plan & DCF'!$C$6)^3+H22/(1+'Business Plan & DCF'!$C$6)^4+I22/(1+'Business Plan & DCF'!$C$6)^5+J22/(1+'Business Plan & DCF'!$C$6)^6+K22/(1+'Business Plan & DCF'!$C$6)^7+L22/(1+'Business Plan & DCF'!$C$6)^8+M22/(1+'Business Plan & DCF'!$C$6)^9+N22/(1+'Business Plan & DCF'!$C$6)^10+N22*(1+'Business Plan & DCF'!$C$7)/('Business Plan & DCF'!$C$6-'Business Plan & DCF'!$C$7)/(1+'Business Plan & DCF'!$C$6)^10 -> 2406.4962
E21: =$B$20 -> 0.1 | F21: =$B$20 -> 0.1 | G21: =$B$20 -> 0.1 | H21: =$B$20 -> 0.1 | I21: =$B$20 -> 0.1 | J21: =I21+('Business Plan & DCF'!$C$7-$B$20)/5 -> 0.091 | K21: =J21+('Business Plan & DCF'!$C$7-$B$20)/5 -> 0.082 | L21: =K21+('Business Plan & DCF'!$C$7-$B$20)/5 -> 0.073 | M21: =L21+('Business Plan & DCF'!$C$7-$B$20)/5 -> 0.064 | N21: =M21+('Business Plan & DCF'!$C$7-$B$20)/5 -> 0.055
E22: =(E20*$C$20-E20*Inputs!$C$47)*(1-Inputs!$C$30)+E20*Inputs!$C$47-E20*Inputs!$C$48-(E20-D20)*Inputs!$C$49 -> 94.125 | F22: =(F20*$C$20-F20*Inputs!$C$47)*(1-Inputs!$C$30)+F20*Inputs!$C$47-F20*Inputs!$C$48-(F20-E20)*Inputs!$C$49 -> 103.5375 | G22: =(G20*$C$20-G20*Inputs!$C$47)*(1-Inputs!$C$30)+G20*Inputs!$C$47-G20*Inputs!$C$48-(G20-F20)*Inputs!$C$49 -> 113.89125 | H22: =(H20*$C$20-H20*Inputs!$C$47)*(1-Inputs!$C$30)+H20*Inputs!$C$47-H20*Inputs!$C$48-(H20-G20)*Inputs!$C$49 -> 125.28038 | I22: =(I20*$C$20-I20*Inputs!$C$47)*(1-Inputs!$C$30)+I20*Inputs!$C$47-I20*Inputs!$C$48-(I20-H20)*Inputs!$C$49 -> 137.80841 | J22: =(J20*$C$20-J20*Inputs!$C$47)*(1-Inputs!$C$30)+J20*Inputs!$C$47-J20*Inputs!$C$48-(J20-I20)*Inputs!$C$49 -> 151.5349 | K22: =(K20*$C$20-K20*Inputs!$C$47)*(1-Inputs!$C$30)+K20*Inputs!$C$47-K20*Inputs!$C$48-(K20-J20)*Inputs!$C$49 -> 165.26527 | L22: =(L20*$C$20-L20*Inputs!$C$47)*(1-Inputs!$C$30)+L20*Inputs!$C$47-L20*Inputs!$C$48-(L20-K20)*Inputs!$C$49 -> 178.75286 | ... N22: =(N20*$C$20-N20*Inputs!$C$47)*(1-Inputs!$C$30)+N20*Inputs!$C$47-N20*Inputs!$C$48-(N20-M20)*Inputs!$C$49 -> 203.93063
B23: =Sensitivity!$B$8 -> 0.1 | C23: =Sensitivity!$E$6 -> 0.22 | D23: =Inputs!$C$9 -> 750 | E23: =D23*(1+E24) -> 825 | F23: =E23*(1+F24) -> 907.5 | G23: =F23*(1+G24) -> 998.25 | H23: =G23*(1+H24) -> 1098.075 | I23: =H23*(1+I24) -> 1207.8825 | J23: =I23*(1+J24) -> 1317.7998 | K23: =J23*(1+K24) -> 1425.8594 | L23: =K23*(1+L24) -> 1529.9471 | ... N23: =M23*(1+N24) -> 1717.3962 | O23: =E25/(1+'Business Plan & DCF'!$C$6)^1+F25/(1+'Business Plan & DCF'!$C$6)^2+G25/(1+'Business Plan & DCF'!$C$6)^3+H25/(1+'Business Plan & DCF'!$C$6)^4+I25/(1+'Business Plan & DCF'!$C$6)^5+J25/(1+'Business Plan & DCF'!$C$6)^6+K25/(1+'Business Plan & DCF'!$C$6)^7+L25/(1+'Business Plan & DCF'!$C$6)^8+M25/(1+'Business Plan & DCF'!$C$6)^9+N25/(1+'Business Plan & DCF'!$C$6)^10+N25*(1+'Business Plan & DCF'!$C$7)/('Business Plan & DCF'!$C$6-'Business Plan & DCF'!$C$7)/(1+'Business Plan & DCF'!$C$6)^10 -> 2713.5082
E24: =$B$23 -> 0.1 | F24: =$B$23 -> 0.1 | G24: =$B$23 -> 0.1 | H24: =$B$23 -> 0.1 | I24: =$B$23 -> 0.1 | J24: =I24+('Business Plan & DCF'!$C$7-$B$23)/5 -> 0.091 | K24: =J24+('Business Plan & DCF'!$C$7-$B$23)/5 -> 0.082 | L24: =K24+('Business Plan & DCF'!$C$7-$B$23)/5 -> 0.073 | M24: =L24+('Business Plan & DCF'!$C$7-$B$23)/5 -> 0.064 | N24: =M24+('Business Plan & DCF'!$C$7-$B$23)/5 -> 0.055
E25: =(E23*$C$23-E23*Inputs!$C$47)*(1-Inputs!$C$30)+E23*Inputs!$C$47-E23*Inputs!$C$48-(E23-D23)*Inputs!$C$49 -> 106.5 | F25: =(F23*$C$23-F23*Inputs!$C$47)*(1-Inputs!$C$30)+F23*Inputs!$C$47-F23*Inputs!$C$48-(F23-E23)*Inputs!$C$49 -> 117.15 | G25: =(G23*$C$23-G23*Inputs!$C$47)*(1-Inputs!$C$30)+G23*Inputs!$C$47-G23*Inputs!$C$48-(G23-F23)*Inputs!$C$49 -> 128.865 | H25: =(H23*$C$23-H23*Inputs!$C$47)*(1-Inputs!$C$30)+H23*Inputs!$C$47-H23*Inputs!$C$48-(H23-G23)*Inputs!$C$49 -> 141.7515 | I25: =(I23*$C$23-I23*Inputs!$C$47)*(1-Inputs!$C$30)+I23*Inputs!$C$47-I23*Inputs!$C$48-(I23-H23)*Inputs!$C$49 -> 155.92665 | J25: =(J23*$C$23-J23*Inputs!$C$47)*(1-Inputs!$C$30)+J23*Inputs!$C$47-J23*Inputs!$C$48-(J23-I23)*Inputs!$C$49 -> 171.3019 | K25: =(K23*$C$23-K23*Inputs!$C$47)*(1-Inputs!$C$30)+K23*Inputs!$C$47-K23*Inputs!$C$48-(K23-J23)*Inputs!$C$49 -> 186.65316 | L25: =(L23*$C$23-L23*Inputs!$C$47)*(1-Inputs!$C$30)+L23*Inputs!$C$47-L23*Inputs!$C$48-(L23-K23)*Inputs!$C$49 -> 201.70207 | ... N25: =(N23*$C$23-N23*Inputs!$C$47)*(1-Inputs!$C$30)+N23*Inputs!$C$47-N23*Inputs!$C$48-(N23-M23)*Inputs!$C$49 -> 229.69157
B26: =Sensitivity!$B$8 -> 0.1 | C26: =Sensitivity!$F$6 -> 0.24 | D26: =Inputs!$C$9 -> 750 | E26: =D26*(1+E27) -> 825 | F26: =E26*(1+F27) -> 907.5 | G26: =F26*(1+G27) -> 998.25 | H26: =G26*(1+H27) -> 1098.075 | I26: =H26*(1+I27) -> 1207.8825 | J26: =I26*(1+J27) -> 1317.7998 | K26: =J26*(1+K27) -> 1425.8594 | L26: =K26*(1+L27) -> 1529.9471 | ... N26: =M26*(1+N27) -> 1717.3962 | O26: =E28/(1+'Business Plan & DCF'!$C$6)^1+F28/(1+'Business Plan & DCF'!$C$6)^2+G28/(1+'Business Plan & DCF'!$C$6)^3+H28/(1+'Business Plan & DCF'!$C$6)^4+I28/(1+'Business Plan & DCF'!$C$6)^5+J28/(1+'Business Plan & DCF'!$C$6)^6+K28/(1+'Business Plan & DCF'!$C$6)^7+L28/(1+'Business Plan & DCF'!$C$6)^8+M28/(1+'Business Plan & DCF'!$C$6)^9+N28/(1+'Business Plan & DCF'!$C$6)^10+N28*(1+'Business Plan & DCF'!$C$7)/('Business Plan & DCF'!$C$6-'Business Plan & DCF'!$C$7)/(1+'Business Plan & DCF'!$C$6)^10 -> 3020.5201
E27: =$B$26 -> 0.1 | F27: =$B$26 -> 0.1 | G27: =$B$26 -> 0.1 | H27: =$B$26 -> 0.1 | I27: =$B$26 -> 0.1 | J27: =I27+('Business Plan & DCF'!$C$7-$B$26)/5 -> 0.091 | K27: =J27+('Business Plan & DCF'!$C$7-$B$26)/5 -> 0.082 | L27: =K27+('Business Plan & DCF'!$C$7-$B$26)/5 -> 0.073 | M27: =L27+('Business Plan & DCF'!$C$7-$B$26)/5 -> 0.064 | N27: =M27+('Business Plan & DCF'!$C$7-$B$26)/5 -> 0.055
